<?xml version="1.0" ?>
<!-- =================================================================================== -->
<!-- |    This document was autogenerated by xacro from hexapod.xacro                  | -->
<!-- |    EDITING THIS FILE BY HAND IS NOT RECOMMENDED                                 | -->
<!-- =================================================================================== -->
<robot name="hexapod" xmlns:xacro="http://www.ros.org/wiki/xacro">
  <link name="base_link">
    <visual>
      <origin rpy="1.57 0 0"/>
      <geometry>
        <mesh filename="package://model/meshes/body_bin.stl"/>
      </geometry>
      <material name="abs">
        <color rgba="0.6 0.6 0.6 1"/>
      </material>
      <collision>
        <mesh filename="package://model/meshes/body_bin.stl"/>
      </collision>
    </visual>
  </link>
  <link name="leg_l_1_f1">
    <visual>
      <origin rpy="0 1.57 -1.57" xyz="-0.009 0 0"/>
      <geometry>
        <mesh filename="package://model/meshes/femur_1_bin.stl"/>
      </geometry>
      <material name="abs1">
        <color rgba="0.9 0.0 0.0 1"/>
      </material>
    </visual>
  </link>
  <link name="leg_l_1_f3">
    <visual>
      <origin rpy="4.71 0 1.57" xyz="0 -0.053 0.013"/>
      <geometry>
        <mesh filename="package://model/meshes/femur_3_bin.stl"/>
      </geometry>
      <material name="abs2">
        <color rgba="0.0 0.9 0.0 1"/>
      </material>
    </visual>
  </link>
  <link name="leg_l_1_f2">
    <visual>
      <origin rpy="4.71 0 0" xyz="-0.063 0 0.013"/>
      <geometry>
        <mesh filename="package://model/meshes/femur_2_bin.stl"/>
      </geometry>
      <material name="abs3">
        <color rgba="0.0 0.0 0.9 1"/>
      </material>
    </visual>
  </link>
  <link name="leg_l_1_f4">
    <visual>
      <origin rpy="1.57 0 4.71" xyz="0 0.038 -0.013"/>
      <geometry>
        <mesh filename="package://model/meshes/femur_4_bin.stl"/>
      </geometry>
      <material name="abs4">
        <color rgba="0.8 0.8 0.0 1"/>
      </material>
    </visual>
  </link>
  <joint name="joint_l_1_f1" type="revolute">
    <parent link="base_link"/>
    <child link="leg_l_1_f1"/>
    <origin rpy="0 0 0.7" xyz="0.103 0.07 0"/>
    <axis xyz="0 0 1"/>
    <limit effort="15" lower="-1.57" upper="1.57" velocity="1.0"/>
  </joint>
  <joint name="joint_l_1_f3" type="revolute">
    <parent link="leg_l_1_f1"/>
    <child link="leg_l_1_f3"/>
    <origin rpy="-1.1 0 1.57" xyz="0.062 0.0 0.0"/>
    <axis xyz="1 0 0"/>
    <limit effort="15" lower="-1.57" upper="1.57" velocity="1.0"/>
  </joint>
  <joint name="joint_l_1_f2" type="revolute">
    <parent link="leg_l_1_f3"/>
    <child link="leg_l_1_f2"/>
    <origin rpy="0 -2.3 1.57" xyz="0.0 -0.094 0.0"/>
    <axis xyz="0 1 0"/>
    <limit effort="15" lower="-1.57" upper="1.57" velocity="1.0"/>
  </joint>
  <joint name="joint_l_1_f4" type="revolute">
    <parent link="leg_l_1_f2"/>
    <child link="leg_l_1_f4"/>
    <origin rpy="-0.4 0 1.57" xyz="-0.104 0.0 0.0"/>
    <axis xyz="1 0 0"/>
    <limit effort="15" lower="-1.57" upper="1.57" velocity="1.0"/>
  </joint>
  <link name="leg_l_2_f1">
    <visual>
      <origin rpy="0 1.57 -1.57" xyz="-0.009 0 0"/>
      <geometry>
        <mesh filename="package://model/meshes/femur_1_bin.stl"/>
      </geometry>
      <material name="abs1">
        <color rgba="0.9 0.0 0.0 1"/>
      </material>
    </visual>
  </link>
  <link name="leg_l_2_f3">
    <visual>
      <origin rpy="4.71 0 1.57" xyz="0 -0.053 0.013"/>
      <geometry>
        <mesh filename="package://model/meshes/femur_3_bin.stl"/>
      </geometry>
      <material name="abs2">
        <color rgba="0.0 0.9 0.0 1"/>
      </material>
    </visual>
  </link>
  <link name="leg_l_2_f2">
    <visual>
      <origin rpy="4.71 0 0" xyz="-0.063 0 0.013"/>
      <geometry>
        <mesh filename="package://model/meshes/femur_2_bin.stl"/>
      </geometry>
      <material name="abs3">
        <color rgba="0.0 0.0 0.9 1"/>
      </material>
    </visual>
  </link>
  <link name="leg_l_2_f4">
    <visual>
      <origin rpy="1.57 0 4.71" xyz="0 0.038 -0.013"/>
      <geometry>
        <mesh filename="package://model/meshes/femur_4_bin.stl"/>
      </geometry>
      <material name="abs4">
        <color rgba="0.8 0.8 0.0 1"/>
      </material>
    </visual>
  </link>
  <joint name="joint_l_2_f1" type="revolute">
    <parent link="base_link"/>
    <child link="leg_l_2_f1"/>
    <origin rpy="0 0 1.4" xyz="0.0 0.096 0"/>
    <axis xyz="0 0 1"/>
    <limit effort="15" lower="-1.57" upper="1.57" velocity="1.0"/>
  </joint>
  <joint name="joint_l_2_f3" type="revolute">
    <parent link="leg_l_2_f1"/>
    <child link="leg_l_2_f3"/>
    <origin rpy="-1.1 0 1.57" xyz="0.062 0.0 0.0"/>
    <axis xyz="1 0 0"/>
    <limit effort="15" lower="-1.57" upper="1.57" velocity="1.0"/>
  </joint>
  <joint name="joint_l_2_f2" type="revolute">
    <parent link="leg_l_2_f3"/>
    <child link="leg_l_2_f2"/>
    <origin rpy="0 -2.3 1.57" xyz="0.0 -0.094 0.0"/>
    <axis xyz="1 0 0"/>
    <limit effort="15" lower="-1.57" upper="1.57" velocity="1.0"/>
  </joint>
  <joint name="joint_l_2_f4" type="revolute">
    <parent link="leg_l_2_f2"/>
    <child link="leg_l_2_f4"/>
    <origin rpy="-0.4 0 1.57" xyz="-0.104 0.0 0.0"/>
    <axis xyz="1 0 0"/>
    <limit effort="15" lower="-1.57" upper="1.57" velocity="1.0"/>
  </joint>
  <link name="leg_l_3_f1">
    <visual>
      <origin rpy="0 1.57 -1.57" xyz="-0.009 0 0"/>
      <geometry>
        <mesh filename="package://model/meshes/femur_1_bin.stl"/>
      </geometry>
      <material name="abs1">
        <color rgba="0.9 0.0 0.0 1"/>
      </material>
    </visual>
  </link>
  <link name="leg_l_3_f3">
    <visual>
      <origin rpy="4.71 0 1.57" xyz="0 -0.053 0.013"/>
      <geometry>
        <mesh filename="package://model/meshes/femur_3_bin.stl"/>
      </geometry>
      <material name="abs2">
        <color rgba="0.0 0.9 0.0 1"/>
      </material>
    </visual>
  </link>
  <link name="leg_l_3_f2">
    <visual>
      <origin rpy="4.71 0 0" xyz="-0.063 0 0.013"/>
      <geometry>
        <mesh filename="package://model/meshes/femur_2_bin.stl"/>
      </geometry>
      <material name="abs3">
        <color rgba="0.0 0.0 0.9 1"/>
      </material>
    </visual>
  </link>
  <link name="leg_l_3_f4">
    <visual>
      <origin rpy="1.57 0 4.71" xyz="0 0.038 -0.013"/>
      <geometry>
        <mesh filename="package://model/meshes/femur_4_bin.stl"/>
      </geometry>
      <material name="abs4">
        <color rgba="0.8 0.8 0.0 1"/>
      </material>
    </visual>
  </link>
  <joint name="joint_l_3_f1" type="revolute">
    <parent link="base_link"/>
    <child link="leg_l_3_f1"/>
    <origin rpy="0 0 2.1" xyz="-0.09 0.083 0"/>
    <axis xyz="0 0 1"/>
    <limit effort="15" lower="-1.57" upper="1.57" velocity="1.0"/>
  </joint>
  <joint name="joint_l_3_f3" type="revolute">
    <parent link="leg_l_3_f1"/>
    <child link="leg_l_3_f3"/>
    <origin rpy="-1.1 0 1.57" xyz="0.062 0.0 0.0"/>
    <axis xyz="1 0 0"/>
    <limit effort="15" lower="-1.57" upper="1.57" velocity="1.0"/>
  </joint>
  <joint name="joint_l_3_f2" type="revolute">
    <parent link="leg_l_3_f3"/>
    <child link="leg_l_3_f2"/>
    <origin rpy="0 -2.3 1.57" xyz="0.0 -0.094 0.0"/>
    <axis xyz="1 0 0"/>
    <limit effort="15" lower="-1.57" upper="1.57" velocity="1.0"/>
  </joint>
  <joint name="joint_l_3_f4" type="revolute">
    <parent link="leg_l_3_f2"/>
    <child link="leg_l_3_f4"/>
    <origin rpy="-0.4 0 1.57" xyz="-0.104 0.0 0.0"/>
    <axis xyz="1 0 0"/>
    <limit effort="15" lower="-1.57" upper="1.57" velocity="1.0"/>
  </joint>
  <link name="leg__1_f1">
    <visual>
      <origin rpy="0 1.57 -1.57" xyz="-0.009 0 0"/>
      <geometry>
        <mesh filename="package://model/meshes/femur_1_bin.stl"/>
      </geometry>
      <material name="abs1">
        <color rgba="0.9 0.0 0.0 1"/>
      </material>
    </visual>
  </link>
  <link name="leg__1_f3">
    <visual>
      <origin rpy="4.71 0 1.57" xyz="0 -0.053 0.013"/>
      <geometry>
        <mesh filename="package://model/meshes/femur_3_bin.stl"/>
      </geometry>
      <material name="abs2">
        <color rgba="0.0 0.9 0.0 1"/>
      </material>
    </visual>
  </link>
  <link name="leg__1_f2">
    <visual>
      <origin rpy="4.71 0 0" xyz="-0.063 0 0.013"/>
      <geometry>
        <mesh filename="package://model/meshes/femur_2_bin.stl"/>
      </geometry>
      <material name="abs3">
        <color rgba="0.0 0.0 0.9 1"/>
      </material>
    </visual>
  </link>
  <link name="leg__1_f4">
    <visual>
      <origin rpy="1.57 0 4.71" xyz="0 0.038 -0.013"/>
      <geometry>
        <mesh filename="package://model/meshes/femur_4_bin.stl"/>
      </geometry>
      <material name="abs4">
        <color rgba="0.8 0.8 0.0 1"/>
      </material>
    </visual>
  </link>
  <joint name="joint__1_f1" type="revolute">
    <parent link="base_link"/>
    <child link="leg__1_f1"/>
    <origin rpy="0 0 -0.7" xyz="0.103 -0.07 0"/>
    <axis xyz="0 0 1"/>
    <limit effort="15" lower="-1.57" upper="1.57" velocity="1.0"/>
  </joint>
  <joint name="joint__1_f3" type="revolute">
    <parent link="leg__1_f1"/>
    <child link="leg__1_f3"/>
    <origin rpy="-1.1 0 1.57" xyz="0.062 0.0 0.0"/>
    <axis xyz="1 0 0"/>
    <limit effort="15" lower="-1.57" upper="1.57" velocity="1.0"/>
  </joint>
  <joint name="joint__1_f2" type="revolute">
    <parent link="leg__1_f3"/>
    <child link="leg__1_f2"/>
    <origin rpy="0 -2.3 1.57" xyz="0.0 -0.094 0.0"/>
    <axis xyz="1 0 0"/>
    <limit effort="15" lower="-1.57" upper="1.57" velocity="1.0"/>
  </joint>
  <joint name="joint__1_f4" type="revolute">
    <parent link="leg__1_f2"/>
    <child link="leg__1_f4"/>
    <origin rpy="-0.4 0 1.57" xyz="-0.104 0.0 0.0"/>
    <axis xyz="1 0 0"/>
    <limit effort="15" lower="-1.57" upper="1.57" velocity="1.0"/>
  </joint>
  <link name="leg_r_2_f1">
    <visual>
      <origin rpy="0 1.57 -1.57" xyz="-0.009 0 0"/>
      <geometry>
        <mesh filename="package://model/meshes/femur_1_bin.stl"/>
      </geometry>
      <material name="abs1">
        <color rgba="0.9 0.0 0.0 1"/>
      </material>
    </visual>
  </link>
  <link name="leg_r_2_f3">
    <visual>
      <origin rpy="4.71 0 1.57" xyz="0 -0.053 0.013"/>
      <geometry>
        <mesh filename="package://model/meshes/femur_3_bin.stl"/>
      </geometry>
      <material name="abs2">
        <color rgba="0.0 0.9 0.0 1"/>
      </material>
    </visual>
  </link>
  <link name="leg_r_2_f2">
    <visual>
      <origin rpy="4.71 0 0" xyz="-0.063 0 0.013"/>
      <geometry>
        <mesh filename="package://model/meshes/femur_2_bin.stl"/>
      </geometry>
      <material name="abs3">
        <color rgba="0.0 0.0 0.9 1"/>
      </material>
    </visual>
  </link>
  <link name="leg_r_2_f4">
    <visual>
      <origin rpy="1.57 0 4.71" xyz="0 0.038 -0.013"/>
      <geometry>
        <mesh filename="package://model/meshes/femur_4_bin.stl"/>
      </geometry>
      <material name="abs4">
        <color rgba="0.8 0.8 0.0 1"/>
      </material>
    </visual>
  </link>
  <joint name="joint_r_2_f1" type="revolute">
    <parent link="base_link"/>
    <child link="leg_r_2_f1"/>
    <origin rpy="0 0 -1.4" xyz="0.0 -0.096 0"/>
    <axis xyz="0 0 1"/>
    <limit effort="15" lower="-1.57" upper="1.57" velocity="1.0"/>
  </joint>
  <joint name="joint_r_2_f3" type="revolute">
    <parent link="leg_r_2_f1"/>
    <child link="leg_r_2_f3"/>
    <origin rpy="-1.1 0 1.57" xyz="0.062 0.0 0.0"/>
    <axis xyz="1 0 0"/>
    <limit effort="15" lower="-1.57" upper="1.57" velocity="1.0"/>
  </joint>
  <joint name="joint_r_2_f2" type="revolute">
    <parent link="leg_r_2_f3"/>
    <child link="leg_r_2_f2"/>
    <origin rpy="0 -2.3 1.57" xyz="0.0 -0.094 0.0"/>
    <axis xyz="1 0 0"/>
    <limit effort="15" lower="-1.57" upper="1.57" velocity="1.0"/>
  </joint>
  <joint name="joint_r_2_f4" type="revolute">
    <parent link="leg_r_2_f2"/>
    <child link="leg_r_2_f4"/>
    <origin rpy="-0.4 0 1.57" xyz="-0.104 0.0 0.0"/>
    <axis xyz="1 0 0"/>
    <limit effort="15" lower="-1.57" upper="1.57" velocity="1.0"/>
  </joint>
  <link name="leg_r_3_f1">
    <visual>
      <origin rpy="0 1.57 -1.57" xyz="-0.009 0 0"/>
      <geometry>
        <mesh filename="package://model/meshes/femur_1_bin.stl"/>
      </geometry>
      <material name="abs1">
        <color rgba="0.9 0.0 0.0 1"/>
      </material>
    </visual>
  </link>
  <link name="leg_r_3_f3">
    <visual>
      <origin rpy="4.71 0 1.57" xyz="0 -0.053 0.013"/>
      <geometry>
        <mesh filename="package://model/meshes/femur_3_bin.stl"/>
      </geometry>
      <material name="abs2">
        <color rgba="0.0 0.9 0.0 1"/>
      </material>
    </visual>
  </link>
  <link name="leg_r_3_f2">
    <visual>
      <origin rpy="4.71 0 0" xyz="-0.063 0 0.013"/>
      <geometry>
        <mesh filename="package://model/meshes/femur_2_bin.stl"/>
      </geometry>
      <material name="abs3">
        <color rgba="0.0 0.0 0.9 1"/>
      </material>
    </visual>
  </link>
  <link name="leg_r_3_f4">
    <visual>
      <origin rpy="1.57 0 4.71" xyz="0 0.038 -0.013"/>
      <geometry>
        <mesh filename="package://model/meshes/femur_4_bin.stl"/>
      </geometry>
      <material name="abs4">
        <color rgba="0.8 0.8 0.0 1"/>
      </material>
    </visual>
  </link>
  <joint name="joint_r_3_f1" type="revolute">
    <parent link="base_link"/>
    <child link="leg_r_3_f1"/>
    <origin rpy="0 0 -2.1" xyz="-0.09 -0.083 0"/>
    <axis xyz="0 0 1"/>
    <limit effort="15" lower="-1.57" upper="1.57" velocity="1.0"/>
  </joint>
  <joint name="joint_r_3_f3" type="revolute">
    <parent link="leg_r_3_f1"/>
    <child link="leg_r_3_f3"/>
    <origin rpy="-1.1 0 1.57" xyz="0.062 0.0 0.0"/>
    <axis xyz="1 0 0"/>
    <limit effort="15" lower="-1.57" upper="1.57" velocity="1.0"/>
  </joint>
  <joint name="joint_r_3_f2" type="revolute">
    <parent link="leg_r_3_f3"/>
    <child link="leg_r_3_f2"/>
    <origin rpy="0 -2.3 1.57" xyz="0.0 -0.094 0.0"/>
    <axis xyz="1 0 0"/>
    <limit effort="15" lower="-1.57" upper="1.57" velocity="1.0"/>
  </joint>
  <joint name="joint_r_3_f4" type="revolute">
    <parent link="leg_r_3_f2"/>
    <child link="leg_r_3_f4"/>
    <origin rpy="-0.4 0 1.57" xyz="-0.104 0.0 0.0"/>
    <axis xyz="1 0 0"/>
    <limit effort="15" lower="-1.57" upper="1.57" velocity="1.0"/>
  </joint>
  <model_state model="hexapod" time_stamp="0.1">
    <joint_state joint="joint_l_1_f1" position="1.57"/>
    <joint_state joint="joint_l_1_f2" position="1.57"/>
  </model_state>
</robot>

