<?xml version="1.0" ?>
<!-- =================================================================================== -->
<!-- |    This document was autogenerated by xacro from hexapod.xacro                  | -->
<!-- |    EDITING THIS FILE BY HAND IS NOT RECOMMENDED                                 | -->
<!-- =================================================================================== -->
<robot name="hexapod" xmlns:xacro="http://www.ros.org/wiki/xacro">
  <link name="base_link">
    <visual>
      <origin rpy="1.57079632679 0 0"/>
      <geometry>
        <mesh filename="package://hexapod_model/meshes/body_bin.stl"/>
      </geometry>
      <material name="abs">
        <color rgba="0.6 0.6 0.6 1"/>
      </material>
    </visual>
    <collision>
      <origin rpy="1.57079632679 0 0"/>
      <geometry>
        <box size="0.19 0.05 0.14"/>
      </geometry>
    </collision>
  </link>
  <link name="leg_l_1_f1">
    <visual>
      <origin rpy="0 1.57079632679 -1.57079632679" xyz="-0.009 0 0"/>
      <geometry>
        <mesh filename="package://hexapod_model/meshes/femur_1_bin.stl"/>
      </geometry>
      <material name="abs1">
        <color rgba="0.9 0.0 0.0 1"/>
      </material>
    </visual>
    <collision>
      <origin rpy="0 1.57079632679 -1.57079632679" xyz="0.04 0 0"/>
      <geometry>
        <box size="0.05 0.07 0.05"/>
      </geometry>
    </collision>
  </link>
  <link name="leg_l_1_f2">
    <visual>
      <origin rpy="4.71238898038 0 1.57079632679" xyz="0 -0.053 0.013"/>
      <geometry>
        <mesh filename="package://hexapod_model/meshes/femur_3_bin.stl"/>
      </geometry>
      <material name="abs2">
        <color rgba="0.0 0.9 0.0 1"/>
      </material>
    </visual>
    <collision>
      <origin rpy="4.71238898038 0 1.57079632679" xyz="0 -0.043 0"/>
      <geometry>
        <box size="0.11 0.03 0.06"/>
      </geometry>
    </collision>
  </link>
  <link name="leg_l_1_f3">
    <visual>
      <origin rpy="4.71238898038 0 0" xyz="-0.063 0 0.013"/>
      <geometry>
        <mesh filename="package://hexapod_model/meshes/femur_2_bin.stl"/>
      </geometry>
      <material name="abs3">
        <color rgba="0.0 0.0 0.9 1"/>
      </material>
    </visual>
    <collision>
      <origin rpy="4.71238898038 0 0" xyz="-0.043 0 0"/>
      <geometry>
        <box size="0.12 0.03 0.06"/>
      </geometry>
    </collision>
  </link>
  <link name="leg_l_1_f4">
    <visual>
      <origin rpy="1.57079632679 0 4.71238898038" xyz="0 0.038 -0.013"/>
      <geometry>
        <mesh filename="package://hexapod_model/meshes/femur_4_bin.stl"/>
      </geometry>
      <material name="abs4">
        <color rgba="0.8 0.8 0.0 1"/>
      </material>
    </visual>
    <collision>
      <origin rpy="1.57079632679 0 4.71238898038" xyz="0 0.028 0"/>
      <geometry>
        <box size="0.08 0.03 0.06"/>
      </geometry>
    </collision>
  </link>
  <link name="leg_l_1_end">
    <visual>
      <geometry>
        <box size="0.02 0.005 0.02 "/>
      </geometry>
      <material name="abs_end">
        <color rgba="1 1 1 1"/>
      </material>
    </visual>
    <collision>
      <geometry>
        <box size="0.02 0.005 0.02 "/>
      </geometry>
    </collision>
  </link>
  <joint name="joint_l_1_f1" type="revolute">
    <parent link="base_link"/>
    <child link="leg_l_1_f1"/>
    <origin rpy="0 0 1.57079632679" xyz="0.103 0.07 0"/>
    <axis xyz="0 0 1"/>
    <limit effort="15" lower="-1.57079632679" upper="1.57079632679" velocity="1.0"/>
  </joint>
  <joint name="joint_l_1_f2" type="revolute">
    <parent link="leg_l_1_f1"/>
    <child link="leg_l_1_f2"/>
    <origin rpy="0 0 1.57079632679" xyz="0.062 0.0 0.0"/>
    <axis xyz="1 0 0"/>
    <limit effort="15" lower="-1.57079632679" upper="1.57079632679" velocity="1.0"/>
  </joint>
  <joint name="joint_l_1_f3" type="revolute">
    <parent link="leg_l_1_f2"/>
    <child link="leg_l_1_f3"/>
    <origin rpy="0 -1.00530964915 1.57079632679" xyz="0.0 -0.094 0.0"/>
    <axis xyz="0 1 0"/>
    <limit effort="15" lower="-1.57079632679" upper="1.57079632679" velocity="1.0"/>
  </joint>
  <joint name="joint_l_1_f4" type="revolute">
    <parent link="leg_l_1_f3"/>
    <child link="leg_l_1_f4"/>
    <origin rpy="-0 0 1.57079632679" xyz="-0.104 0.0 0.0"/>
    <axis xyz="1 0 0"/>
    <limit effort="15" lower="-1.57079632679" upper="1.57079632679" velocity="1.0"/>
  </joint>
  <joint name="joint_l_1_end" type="fixed">
    <parent link="leg_l_1_f4"/>
    <child link="leg_l_1_end"/>
    <origin rpy="0 0 0" xyz="0 0.067 0.0"/>
  </joint>
  <link name="leg_l_2_f1">
    <visual>
      <origin rpy="0 1.57079632679 -1.57079632679" xyz="-0.009 0 0"/>
      <geometry>
        <mesh filename="package://hexapod_model/meshes/femur_1_bin.stl"/>
      </geometry>
      <material name="abs1">
        <color rgba="0.9 0.0 0.0 1"/>
      </material>
    </visual>
    <collision>
      <origin rpy="0 1.57079632679 -1.57079632679" xyz="0.04 0 0"/>
      <geometry>
        <box size="0.05 0.07 0.05"/>
      </geometry>
    </collision>
  </link>
  <link name="leg_l_2_f2">
    <visual>
      <origin rpy="4.71238898038 0 1.57079632679" xyz="0 -0.053 0.013"/>
      <geometry>
        <mesh filename="package://hexapod_model/meshes/femur_3_bin.stl"/>
      </geometry>
      <material name="abs2">
        <color rgba="0.0 0.9 0.0 1"/>
      </material>
    </visual>
    <collision>
      <origin rpy="4.71238898038 0 1.57079632679" xyz="0 -0.043 0"/>
      <geometry>
        <box size="0.11 0.03 0.06"/>
      </geometry>
    </collision>
  </link>
  <link name="leg_l_2_f3">
    <visual>
      <origin rpy="4.71238898038 0 0" xyz="-0.063 0 0.013"/>
      <geometry>
        <mesh filename="package://hexapod_model/meshes/femur_2_bin.stl"/>
      </geometry>
      <material name="abs3">
        <color rgba="0.0 0.0 0.9 1"/>
      </material>
    </visual>
    <collision>
      <origin rpy="4.71238898038 0 0" xyz="-0.043 0 0"/>
      <geometry>
        <box size="0.12 0.03 0.06"/>
      </geometry>
    </collision>
  </link>
  <link name="leg_l_2_f4">
    <visual>
      <origin rpy="1.57079632679 0 4.71238898038" xyz="0 0.038 -0.013"/>
      <geometry>
        <mesh filename="package://hexapod_model/meshes/femur_4_bin.stl"/>
      </geometry>
      <material name="abs4">
        <color rgba="0.8 0.8 0.0 1"/>
      </material>
    </visual>
    <collision>
      <origin rpy="1.57079632679 0 4.71238898038" xyz="0 0.028 0"/>
      <geometry>
        <box size="0.08 0.03 0.06"/>
      </geometry>
    </collision>
  </link>
  <link name="leg_l_2_end">
    <visual>
      <geometry>
        <box size="0.02 0.005 0.02 "/>
      </geometry>
      <material name="abs_end">
        <color rgba="1 1 1 1"/>
      </material>
    </visual>
    <collision>
      <geometry>
        <box size="0.02 0.005 0.02 "/>
      </geometry>
    </collision>
  </link>
  <joint name="joint_l_2_f1" type="revolute">
    <parent link="base_link"/>
    <child link="leg_l_2_f1"/>
    <origin rpy="0 0 1.57079632679" xyz="0.0 0.096 0"/>
    <axis xyz="0 0 1"/>
    <limit effort="15" lower="-1.57079632679" upper="1.57079632679" velocity="1.0"/>
  </joint>
  <joint name="joint_l_2_f2" type="revolute">
    <parent link="leg_l_2_f1"/>
    <child link="leg_l_2_f2"/>
    <origin rpy="0 0 1.57079632679" xyz="0.062 0.0 0.0"/>
    <axis xyz="1 0 0"/>
    <limit effort="15" lower="-1.57079632679" upper="1.57079632679" velocity="1.0"/>
  </joint>
  <joint name="joint_l_2_f3" type="revolute">
    <parent link="leg_l_2_f2"/>
    <child link="leg_l_2_f3"/>
    <origin rpy="0 -1.00530964915 1.57079632679" xyz="0.0 -0.094 0.0"/>
    <axis xyz="0 1 0"/>
    <limit effort="15" lower="-1.57079632679" upper="1.57079632679" velocity="1.0"/>
  </joint>
  <joint name="joint_l_2_f4" type="revolute">
    <parent link="leg_l_2_f3"/>
    <child link="leg_l_2_f4"/>
    <origin rpy="-0 0 1.57079632679" xyz="-0.104 0.0 0.0"/>
    <axis xyz="1 0 0"/>
    <limit effort="15" lower="-1.57079632679" upper="1.57079632679" velocity="1.0"/>
  </joint>
  <joint name="joint_l_2_end" type="fixed">
    <parent link="leg_l_2_f4"/>
    <child link="leg_l_2_end"/>
    <origin rpy="0 0 0" xyz="0 0.067 0.0"/>
  </joint>
  <link name="leg_l_3_f1">
    <visual>
      <origin rpy="0 1.57079632679 -1.57079632679" xyz="-0.009 0 0"/>
      <geometry>
        <mesh filename="package://hexapod_model/meshes/femur_1_bin.stl"/>
      </geometry>
      <material name="abs1">
        <color rgba="0.9 0.0 0.0 1"/>
      </material>
    </visual>
    <collision>
      <origin rpy="0 1.57079632679 -1.57079632679" xyz="0.04 0 0"/>
      <geometry>
        <box size="0.05 0.07 0.05"/>
      </geometry>
    </collision>
  </link>
  <link name="leg_l_3_f2">
    <visual>
      <origin rpy="4.71238898038 0 1.57079632679" xyz="0 -0.053 0.013"/>
      <geometry>
        <mesh filename="package://hexapod_model/meshes/femur_3_bin.stl"/>
      </geometry>
      <material name="abs2">
        <color rgba="0.0 0.9 0.0 1"/>
      </material>
    </visual>
    <collision>
      <origin rpy="4.71238898038 0 1.57079632679" xyz="0 -0.043 0"/>
      <geometry>
        <box size="0.11 0.03 0.06"/>
      </geometry>
    </collision>
  </link>
  <link name="leg_l_3_f3">
    <visual>
      <origin rpy="4.71238898038 0 0" xyz="-0.063 0 0.013"/>
      <geometry>
        <mesh filename="package://hexapod_model/meshes/femur_2_bin.stl"/>
      </geometry>
      <material name="abs3">
        <color rgba="0.0 0.0 0.9 1"/>
      </material>
    </visual>
    <collision>
      <origin rpy="4.71238898038 0 0" xyz="-0.043 0 0"/>
      <geometry>
        <box size="0.12 0.03 0.06"/>
      </geometry>
    </collision>
  </link>
  <link name="leg_l_3_f4">
    <visual>
      <origin rpy="1.57079632679 0 4.71238898038" xyz="0 0.038 -0.013"/>
      <geometry>
        <mesh filename="package://hexapod_model/meshes/femur_4_bin.stl"/>
      </geometry>
      <material name="abs4">
        <color rgba="0.8 0.8 0.0 1"/>
      </material>
    </visual>
    <collision>
      <origin rpy="1.57079632679 0 4.71238898038" xyz="0 0.028 0"/>
      <geometry>
        <box size="0.08 0.03 0.06"/>
      </geometry>
    </collision>
  </link>
  <link name="leg_l_3_end">
    <visual>
      <geometry>
        <box size="0.02 0.005 0.02 "/>
      </geometry>
      <material name="abs_end">
        <color rgba="1 1 1 1"/>
      </material>
    </visual>
    <collision>
      <geometry>
        <box size="0.02 0.005 0.02 "/>
      </geometry>
    </collision>
  </link>
  <joint name="joint_l_3_f1" type="revolute">
    <parent link="base_link"/>
    <child link="leg_l_3_f1"/>
    <origin rpy="0 0 1.57079632679" xyz="-0.09 0.083 0"/>
    <axis xyz="0 0 1"/>
    <limit effort="15" lower="-1.57079632679" upper="1.57079632679" velocity="1.0"/>
  </joint>
  <joint name="joint_l_3_f2" type="revolute">
    <parent link="leg_l_3_f1"/>
    <child link="leg_l_3_f2"/>
    <origin rpy="0 0 1.57079632679" xyz="0.062 0.0 0.0"/>
    <axis xyz="1 0 0"/>
    <limit effort="15" lower="-1.57079632679" upper="1.57079632679" velocity="1.0"/>
  </joint>
  <joint name="joint_l_3_f3" type="revolute">
    <parent link="leg_l_3_f2"/>
    <child link="leg_l_3_f3"/>
    <origin rpy="0 -1.00530964915 1.57079632679" xyz="0.0 -0.094 0.0"/>
    <axis xyz="0 1 0"/>
    <limit effort="15" lower="-1.57079632679" upper="1.57079632679" velocity="1.0"/>
  </joint>
  <joint name="joint_l_3_f4" type="revolute">
    <parent link="leg_l_3_f3"/>
    <child link="leg_l_3_f4"/>
    <origin rpy="-0 0 1.57079632679" xyz="-0.104 0.0 0.0"/>
    <axis xyz="1 0 0"/>
    <limit effort="15" lower="-1.57079632679" upper="1.57079632679" velocity="1.0"/>
  </joint>
  <joint name="joint_l_3_end" type="fixed">
    <parent link="leg_l_3_f4"/>
    <child link="leg_l_3_end"/>
    <origin rpy="0 0 0" xyz="0 0.067 0.0"/>
  </joint>
  <link name="leg_r_1_f1">
    <visual>
      <origin rpy="0 1.57079632679 -1.57079632679" xyz="-0.009 0 0"/>
      <geometry>
        <mesh filename="package://hexapod_model/meshes/femur_1_bin.stl"/>
      </geometry>
      <material name="abs1">
        <color rgba="0.9 0.0 0.0 1"/>
      </material>
    </visual>
    <collision>
      <origin rpy="0 1.57079632679 -1.57079632679" xyz="0.04 0 0"/>
      <geometry>
        <box size="0.05 0.07 0.05"/>
      </geometry>
    </collision>
  </link>
  <link name="leg_r_1_f2">
    <visual>
      <origin rpy="4.71238898038 0 1.57079632679" xyz="0 -0.053 0.013"/>
      <geometry>
        <mesh filename="package://hexapod_model/meshes/femur_3_bin.stl"/>
      </geometry>
      <material name="abs2">
        <color rgba="0.0 0.9 0.0 1"/>
      </material>
    </visual>
    <collision>
      <origin rpy="4.71238898038 0 1.57079632679" xyz="0 -0.043 0"/>
      <geometry>
        <box size="0.11 0.03 0.06"/>
      </geometry>
    </collision>
  </link>
  <link name="leg_r_1_f3">
    <visual>
      <origin rpy="4.71238898038 0 0" xyz="-0.063 0 0.013"/>
      <geometry>
        <mesh filename="package://hexapod_model/meshes/femur_2_bin.stl"/>
      </geometry>
      <material name="abs3">
        <color rgba="0.0 0.0 0.9 1"/>
      </material>
    </visual>
    <collision>
      <origin rpy="4.71238898038 0 0" xyz="-0.043 0 0"/>
      <geometry>
        <box size="0.12 0.03 0.06"/>
      </geometry>
    </collision>
  </link>
  <link name="leg_r_1_f4">
    <visual>
      <origin rpy="1.57079632679 0 4.71238898038" xyz="0 0.038 -0.013"/>
      <geometry>
        <mesh filename="package://hexapod_model/meshes/femur_4_bin.stl"/>
      </geometry>
      <material name="abs4">
        <color rgba="0.8 0.8 0.0 1"/>
      </material>
    </visual>
    <collision>
      <origin rpy="1.57079632679 0 4.71238898038" xyz="0 0.028 0"/>
      <geometry>
        <box size="0.08 0.03 0.06"/>
      </geometry>
    </collision>
  </link>
  <link name="leg_r_1_end">
    <visual>
      <geometry>
        <box size="0.02 0.005 0.02 "/>
      </geometry>
      <material name="abs_end">
        <color rgba="1 1 1 1"/>
      </material>
    </visual>
    <collision>
      <geometry>
        <box size="0.02 0.005 0.02 "/>
      </geometry>
    </collision>
  </link>
  <joint name="joint_r_1_f1" type="revolute">
    <parent link="base_link"/>
    <child link="leg_r_1_f1"/>
    <origin rpy="0 0 -1.57079632679" xyz="0.103 -0.07 0"/>
    <axis xyz="0 0 1"/>
    <limit effort="15" lower="-1.57079632679" upper="1.57079632679" velocity="1.0"/>
  </joint>
  <joint name="joint_r_1_f2" type="revolute">
    <parent link="leg_r_1_f1"/>
    <child link="leg_r_1_f2"/>
    <origin rpy="0 0 1.57079632679" xyz="0.062 0.0 0.0"/>
    <axis xyz="1 0 0"/>
    <limit effort="15" lower="-1.57079632679" upper="1.57079632679" velocity="1.0"/>
  </joint>
  <joint name="joint_r_1_f3" type="revolute">
    <parent link="leg_r_1_f2"/>
    <child link="leg_r_1_f3"/>
    <origin rpy="0 -1.00530964915 1.57079632679" xyz="0.0 -0.094 0.0"/>
    <axis xyz="0 1 0"/>
    <limit effort="15" lower="-1.57079632679" upper="1.57079632679" velocity="1.0"/>
  </joint>
  <joint name="joint_r_1_f4" type="revolute">
    <parent link="leg_r_1_f3"/>
    <child link="leg_r_1_f4"/>
    <origin rpy="-0 0 1.57079632679" xyz="-0.104 0.0 0.0"/>
    <axis xyz="1 0 0"/>
    <limit effort="15" lower="-1.57079632679" upper="1.57079632679" velocity="1.0"/>
  </joint>
  <joint name="joint_r_1_end" type="fixed">
    <parent link="leg_r_1_f4"/>
    <child link="leg_r_1_end"/>
    <origin rpy="0 0 0" xyz="0 0.067 0.0"/>
  </joint>
  <link name="leg_r_2_f1">
    <visual>
      <origin rpy="0 1.57079632679 -1.57079632679" xyz="-0.009 0 0"/>
      <geometry>
        <mesh filename="package://hexapod_model/meshes/femur_1_bin.stl"/>
      </geometry>
      <material name="abs1">
        <color rgba="0.9 0.0 0.0 1"/>
      </material>
    </visual>
    <collision>
      <origin rpy="0 1.57079632679 -1.57079632679" xyz="0.04 0 0"/>
      <geometry>
        <box size="0.05 0.07 0.05"/>
      </geometry>
    </collision>
  </link>
  <link name="leg_r_2_f2">
    <visual>
      <origin rpy="4.71238898038 0 1.57079632679" xyz="0 -0.053 0.013"/>
      <geometry>
        <mesh filename="package://hexapod_model/meshes/femur_3_bin.stl"/>
      </geometry>
      <material name="abs2">
        <color rgba="0.0 0.9 0.0 1"/>
      </material>
    </visual>
    <collision>
      <origin rpy="4.71238898038 0 1.57079632679" xyz="0 -0.043 0"/>
      <geometry>
        <box size="0.11 0.03 0.06"/>
      </geometry>
    </collision>
  </link>
  <link name="leg_r_2_f3">
    <visual>
      <origin rpy="4.71238898038 0 0" xyz="-0.063 0 0.013"/>
      <geometry>
        <mesh filename="package://hexapod_model/meshes/femur_2_bin.stl"/>
      </geometry>
      <material name="abs3">
        <color rgba="0.0 0.0 0.9 1"/>
      </material>
    </visual>
    <collision>
      <origin rpy="4.71238898038 0 0" xyz="-0.043 0 0"/>
      <geometry>
        <box size="0.12 0.03 0.06"/>
      </geometry>
    </collision>
  </link>
  <link name="leg_r_2_f4">
    <visual>
      <origin rpy="1.57079632679 0 4.71238898038" xyz="0 0.038 -0.013"/>
      <geometry>
        <mesh filename="package://hexapod_model/meshes/femur_4_bin.stl"/>
      </geometry>
      <material name="abs4">
        <color rgba="0.8 0.8 0.0 1"/>
      </material>
    </visual>
    <collision>
      <origin rpy="1.57079632679 0 4.71238898038" xyz="0 0.028 0"/>
      <geometry>
        <box size="0.08 0.03 0.06"/>
      </geometry>
    </collision>
  </link>
  <link name="leg_r_2_end">
    <visual>
      <geometry>
        <box size="0.02 0.005 0.02 "/>
      </geometry>
      <material name="abs_end">
        <color rgba="1 1 1 1"/>
      </material>
    </visual>
    <collision>
      <geometry>
        <box size="0.02 0.005 0.02 "/>
      </geometry>
    </collision>
  </link>
  <joint name="joint_r_2_f1" type="revolute">
    <parent link="base_link"/>
    <child link="leg_r_2_f1"/>
    <origin rpy="0 0 -1.57079632679" xyz="0.0 -0.096 0"/>
    <axis xyz="0 0 1"/>
    <limit effort="15" lower="-1.57079632679" upper="1.57079632679" velocity="1.0"/>
  </joint>
  <joint name="joint_r_2_f2" type="revolute">
    <parent link="leg_r_2_f1"/>
    <child link="leg_r_2_f2"/>
    <origin rpy="0 0 1.57079632679" xyz="0.062 0.0 0.0"/>
    <axis xyz="1 0 0"/>
    <limit effort="15" lower="-1.57079632679" upper="1.57079632679" velocity="1.0"/>
  </joint>
  <joint name="joint_r_2_f3" type="revolute">
    <parent link="leg_r_2_f2"/>
    <child link="leg_r_2_f3"/>
    <origin rpy="0 -1.00530964915 1.57079632679" xyz="0.0 -0.094 0.0"/>
    <axis xyz="0 1 0"/>
    <limit effort="15" lower="-1.57079632679" upper="1.57079632679" velocity="1.0"/>
  </joint>
  <joint name="joint_r_2_f4" type="revolute">
    <parent link="leg_r_2_f3"/>
    <child link="leg_r_2_f4"/>
    <origin rpy="-0 0 1.57079632679" xyz="-0.104 0.0 0.0"/>
    <axis xyz="1 0 0"/>
    <limit effort="15" lower="-1.57079632679" upper="1.57079632679" velocity="1.0"/>
  </joint>
  <joint name="joint_r_2_end" type="fixed">
    <parent link="leg_r_2_f4"/>
    <child link="leg_r_2_end"/>
    <origin rpy="0 0 0" xyz="0 0.067 0.0"/>
  </joint>
  <link name="leg_r_3_f1">
    <visual>
      <origin rpy="0 1.57079632679 -1.57079632679" xyz="-0.009 0 0"/>
      <geometry>
        <mesh filename="package://hexapod_model/meshes/femur_1_bin.stl"/>
      </geometry>
      <material name="abs1">
        <color rgba="0.9 0.0 0.0 1"/>
      </material>
    </visual>
    <collision>
      <origin rpy="0 1.57079632679 -1.57079632679" xyz="0.04 0 0"/>
      <geometry>
        <box size="0.05 0.07 0.05"/>
      </geometry>
    </collision>
  </link>
  <link name="leg_r_3_f2">
    <visual>
      <origin rpy="4.71238898038 0 1.57079632679" xyz="0 -0.053 0.013"/>
      <geometry>
        <mesh filename="package://hexapod_model/meshes/femur_3_bin.stl"/>
      </geometry>
      <material name="abs2">
        <color rgba="0.0 0.9 0.0 1"/>
      </material>
    </visual>
    <collision>
      <origin rpy="4.71238898038 0 1.57079632679" xyz="0 -0.043 0"/>
      <geometry>
        <box size="0.11 0.03 0.06"/>
      </geometry>
    </collision>
  </link>
  <link name="leg_r_3_f3">
    <visual>
      <origin rpy="4.71238898038 0 0" xyz="-0.063 0 0.013"/>
      <geometry>
        <mesh filename="package://hexapod_model/meshes/femur_2_bin.stl"/>
      </geometry>
      <material name="abs3">
        <color rgba="0.0 0.0 0.9 1"/>
      </material>
    </visual>
    <collision>
      <origin rpy="4.71238898038 0 0" xyz="-0.043 0 0"/>
      <geometry>
        <box size="0.12 0.03 0.06"/>
      </geometry>
    </collision>
  </link>
  <link name="leg_r_3_f4">
    <visual>
      <origin rpy="1.57079632679 0 4.71238898038" xyz="0 0.038 -0.013"/>
      <geometry>
        <mesh filename="package://hexapod_model/meshes/femur_4_bin.stl"/>
      </geometry>
      <material name="abs4">
        <color rgba="0.8 0.8 0.0 1"/>
      </material>
    </visual>
    <collision>
      <origin rpy="1.57079632679 0 4.71238898038" xyz="0 0.028 0"/>
      <geometry>
        <box size="0.08 0.03 0.06"/>
      </geometry>
    </collision>
  </link>
  <link name="leg_r_3_end">
    <visual>
      <geometry>
        <box size="0.02 0.005 0.02 "/>
      </geometry>
      <material name="abs_end">
        <color rgba="1 1 1 1"/>
      </material>
    </visual>
    <collision>
      <geometry>
        <box size="0.02 0.005 0.02 "/>
      </geometry>
    </collision>
  </link>
  <joint name="joint_r_3_f1" type="revolute">
    <parent link="base_link"/>
    <child link="leg_r_3_f1"/>
    <origin rpy="0 0 -1.57079632679" xyz="-0.09 -0.083 0"/>
    <axis xyz="0 0 1"/>
    <limit effort="15" lower="-1.57079632679" upper="1.57079632679" velocity="1.0"/>
  </joint>
  <joint name="joint_r_3_f2" type="revolute">
    <parent link="leg_r_3_f1"/>
    <child link="leg_r_3_f2"/>
    <origin rpy="0 0 1.57079632679" xyz="0.062 0.0 0.0"/>
    <axis xyz="1 0 0"/>
    <limit effort="15" lower="-1.57079632679" upper="1.57079632679" velocity="1.0"/>
  </joint>
  <joint name="joint_r_3_f3" type="revolute">
    <parent link="leg_r_3_f2"/>
    <child link="leg_r_3_f3"/>
    <origin rpy="0 -1.00530964915 1.57079632679" xyz="0.0 -0.094 0.0"/>
    <axis xyz="0 1 0"/>
    <limit effort="15" lower="-1.57079632679" upper="1.57079632679" velocity="1.0"/>
  </joint>
  <joint name="joint_r_3_f4" type="revolute">
    <parent link="leg_r_3_f3"/>
    <child link="leg_r_3_f4"/>
    <origin rpy="-0 0 1.57079632679" xyz="-0.104 0.0 0.0"/>
    <axis xyz="1 0 0"/>
    <limit effort="15" lower="-1.57079632679" upper="1.57079632679" velocity="1.0"/>
  </joint>
  <joint name="joint_r_3_end" type="fixed">
    <parent link="leg_r_3_f4"/>
    <child link="leg_r_3_end"/>
    <origin rpy="0 0 0" xyz="0 0.067 0.0"/>
  </joint>
</robot>
